<?xml version="1.0"?>
<robot name="robocon_bot" xmlns:xacro="http://www.ros.org/wiki/xacro">

  <!-- Base Link -->
  <link name="base_link">
    <visual>
    <geometry>
      <box size="0.5 0.5 0.2"/>
    </geometry>
    <material name="blue">
      <color rgba="0 0 1 1"/> <!-- blue color -->
    </material>
  </visual>
    <collision>
      <geometry>
        <box size="0.5 0.5 0.2"/>
      </geometry>
    </collision>
    <inertial>
      <mass value="5.0"/>
      <origin xyz="0 0 0"/>
      <inertia ixx="0.1" ixy="0.0" ixz="0.0" iyy="0.1" iyz="0.0" izz="0.1"/>
    </inertial>
  </link>

  <!-- Mecanum Wheels -->
  <xacro:macro name="wheel" params="name xyz r">
    <link name="${name}">
      <visual>
        <geometry>
          <cylinder radius="0.05" length="0.02"/>
        </geometry>
        <material name="black"/>
      </visual>
      <collision>
        <geometry>
          <cylinder radius="0.05" length="0.02"/>
        </geometry>
      </collision>
      <inertial>
        <mass value="1.0"/>
        <origin xyz="0 0 0"/>
        <inertia ixx="0.01" ixy="0.0" ixz="0.0" iyy="0.01" iyz="0.0" izz="0.01"/>
      </inertial>
    </link>
    <joint name="${name}_joint" type="continuous">
      <parent link="base_link"/>
      <child link="${name}"/>
      <origin xyz="${xyz}" rpy="0 0 0"/>
      <axis xyz="0 1 0"/>
    </joint>
  </xacro:macro>

  <xacro:wheel name="wheel_front_left" xyz="0.25 0.25 -0.1" r="0.05"/>
  <xacro:wheel name="wheel_front_right" xyz="0.25 -0.25 -0.1" r="0.05"/>
  <xacro:wheel name="wheel_back_left" xyz="-0.25 0.25 -0.1" r="0.05"/>
  <xacro:wheel name="wheel_back_right" xyz="-0.25 -0.25 -0.1" r="0.05"/>

  <!-- 2D LiDAR -->
  <link name="lidar_link"/>
  <joint name="lidar_joint" type="fixed">
    <parent link="base_link"/>
    <child link="lidar_link"/>
    <origin xyz="0 0 0.15" rpy="0 0 0"/>
  </joint>
  <gazebo reference="lidar_link">
    <sensor type="ray" name="lidar">
      <update_rate>10</update_rate>
      <ray>
        <scan>
          <horizontal>
            <samples>360</samples>
            <resolution>1</resolution>
            <min_angle>-3.1415</min_angle>
            <max_angle>3.1415</max_angle>
          </horizontal>
        </scan>
        <range>
          <min>0.1</min>
          <max>10.0</max>
        </range>
      </ray>
      <plugin name="gazebo_ros_laser" filename="libgazebo_ros_laser.so">
        <topicName>/scan</topicName>
      </plugin>
    </sensor>
  </gazebo>

  <!-- Camera -->
  <link name="camera_link"/>
  <joint name="camera_joint" type="fixed">
    <parent link="base_link"/>
    <child link="camera_link"/>
    <origin xyz="0.1 0 0.2" rpy="0 0 0"/>
  </joint>
  <gazebo reference="camera_link">
    <sensor type="camera" name="camera">
      <camera>
        <horizontal_fov>1.047</horizontal_fov>
        <image>
          <width>640</width>
          <height>480</height>
        </image>
        <clip>
          <near>0.1</near>
          <far>100</far>
        </clip>
      </camera>
      <plugin name="gazebo_ros_camera" filename="libgazebo_ros_camera.so">
        <always_on>true</always_on>
        <update_rate>30</update_rate>
        <camera_name>camera</camera_name>
        <image_topic_name>/camera/image_raw</image_topic_name>
      </plugin>
    </sensor>
  </gazebo>

</robot>
